<?xml version="1.0" ?>
<robot xmlns:xacro="http://ros.org/wiki/xacro">
  <xacro:macro name="servorobotarm" params="prefix">
    <!-- Properties -->
    <material name="servo_black">
          <color rgba="0 0 0 1" />
    </material>
    <material name="servo_slategrey">
          <color rgba="0.4392 0.5019 0.5647 1" />
    </material>

    <!-- link list -->
    <link name="${prefix}base_link">
        <visual>
            <geometry>
                <mesh filename="package://servorobot_support/meshes/servorobot_arm/visual/servorobotarm_base.stl"/>
            </geometry>
            <material name="servo_slategrey"/>
        </visual>
        <collision>
            <geometry>
                <mesh filename="package://servorobot_support/meshes/servorobot_arm/collision/servorobotarm_base.stl"/>
            </geometry>
        </collision>
    </link>
    <link name="${prefix}link_1">
        <visual>
            <geometry>
                <mesh filename="package://servorobot_support/meshes/servorobot_arm/visual/servorobotarm_link_1.stl"/>
            </geometry>
            <material name="servo_slategrey"/>
        </visual>
        <collision>
            <geometry>
                <mesh filename="package://servorobot_support/meshes/servorobot_arm/collision/servorobotarm_link_1.stl"/>
            </geometry>
        </collision>
    </link>
    <link name="${prefix}link_2">
        <visual>
            <geometry>
                <mesh filename="package://servorobot_support/meshes/servorobot_arm/visual/servorobotarm_link_2.stl"/>
            </geometry>
            <material name="servo_slategrey"/>
        </visual>
        <collision>
            <geometry>
                <mesh filename="package://servorobot_support/meshes/servorobot_arm/collision/servorobotarm_link_2.stl"/>
            </geometry>
        </collision>
    </link>
    <link name="${prefix}link_3">
        <visual>
            <geometry>
                <mesh filename="package://servorobot_support/meshes/servorobot_arm/visual/servorobotarm_link_3.stl"/>
            </geometry>
            <material name="servo_slategrey"/>
        </visual>
        <collision>
            <geometry>
                <mesh filename="package://servorobot_support/meshes/servorobot_arm/collision/servorobotarm_link_3.stl"/>
            </geometry>
        </collision>
    </link>
    <link name="${prefix}link_4">
        <visual>
            <geometry>
                <mesh filename="package://servorobot_support/meshes/servorobot_arm/visual/servorobotarm_link_4.stl"/>
            </geometry>
            <material name="servo_slategrey"/>
        </visual>
        <collision>
            <geometry>
                <mesh filename="package://servorobot_support/meshes/servorobot_arm/collision/servorobotarm_link_4.stl"/>
            </geometry>
        </collision>
    </link>
    <link name="${prefix}link_5">
        <visual>
            <geometry>
                <mesh filename="package://servorobot_support/meshes/servorobot_arm/visual/servorobotarm_link_5.stl"/>
            </geometry>
            <material name="servo_slategrey"/>
        </visual>
        <collision>
            <geometry>
                <mesh filename="package://servorobot_support/meshes/servorobot_arm/collision/servorobotarm_link_5.stl"/>
            </geometry>
        </collision>
    </link>
    <link name="${prefix}link_6">
        <visual>
            <geometry>
                <mesh filename="package://servorobot_support/meshes/servorobot_arm/visual/servorobotarm_link_6.stl"/>
            </geometry>
            <material name="servo_slategrey"/>
        </visual>
        <collision>
            <geometry>
                <mesh filename="package://servorobot_support/meshes/servorobot_arm/collision/servorobotarm_link_6.stl"/>
            </geometry>
        </collision>
    </link>
    <!-- end of link list -->

    <!-- joint list -->
    <joint name="${prefix}joint_1" type="revolute">
        <parent link="${prefix}base_link"/>
        <child link="${prefix}link_1"/>
        <origin xyz="0 0 0.450" rpy="0 0 0"/>
        <axis xyz="0 0 1"/>
        <limit lower="-3.1415" upper="3.1415" effort="0" velocity="2.9671"/>
    </joint>
    <joint name="${prefix}joint_2" type="revolute">
      <parent link="${prefix}link_1"/>
      <child link="${prefix}link_2"/>
      <origin xyz="0.320 0 0" rpy="0 0 0"/>
      <axis xyz="0 1 0"/>
      <limit lower="-1.5707" upper="2.7052" effort="0" velocity="2.4434"/>
    </joint>
    <joint name="${prefix}joint_3" type="revolute">
      <parent link="${prefix}link_2"/>
      <child link="${prefix}link_3"/>
      <origin xyz="0 0 0.870" rpy="0 0 0"/>
      <axis xyz="0 -1 0"/>
      <limit lower="-3.1415" upper="3.1415" effort="0" velocity="2.7925"/>
    </joint>
    <joint name="${prefix}joint_4" type="revolute">
      <parent link="${prefix}link_3"/>
      <child link="${prefix}link_4"/>
      <origin xyz="0 0 0.225" rpy="0 0 0"/>
      <axis xyz="-1 0 0"/>
      <limit lower="-6.2831" upper="6.2831" effort="0" velocity="4.0142"/>
    </joint>
    <joint name="${prefix}joint_5" type="revolute">
      <parent link="${prefix}link_4"/>
      <child link="${prefix}link_5"/>
      <origin xyz="1.015 0 0" rpy="0 0 0"/>
      <axis xyz="0 -1 0"/>
      <limit lower="-2.1816" upper="2.1816" effort="0" velocity="4.0142"/>
    </joint>
    <joint name="${prefix}joint_6" type="revolute">
      <parent link="${prefix}link_5"/>
      <child link="${prefix}link_6"/>
      <origin xyz="0.175 0 0" rpy="0 0 0"/>
      <axis xyz="-1 0 0"/>
      <limit lower="-6.2831" upper="6.2831" effort="0" velocity="6.1086"/>
    </joint>
    <!-- end of joint list -->

    <!-- ROS base_link to Robot Manufacturer World Coordinates transform -->
    <link name="${prefix}base" />
    <joint name="${prefix}base_link-base" type="fixed">
        <origin xyz="0 0 0.450" rpy="0 0 0"/>
        <parent link="${prefix}base_link"/>
        <child link="${prefix}base"/>
    </joint>

  </xacro:macro>
</robot>
